Workbook

Sheet Assumptions
A1: Smart Ground — Model Assumptions (all blue cells editable)
A3: HARDWARE — COST & PRICING
A4: SmartBox BOM cost | B4: 75 | C4: CHF — user estimate 70–80 (parts only)
A5: SmartBox assembly & test | B5: 40 | C5: CHF per unit
A6: SmartBox sale price | B6: 250 | C6: CHF — anchored to Promatic Claymate 3-trap wireless kit: USD 675 / 3 traps (promaticusparts.com)
A7: Node hardware cost | B7: 250 | C7: CHF — est., industrial SBC + enclosure
A8: Node rental price | B8: 25 | C8: CHF / month
A9: Hub hardware cost | B9: 400 | C9: CHF — est.
A10: Hub rental price | B10: 50 | C10: CHF / month
A12: SERVICES
A13: Installation day rate (billed) | B13: 1200 | C13: CHF / day
A14: Install days per range (4 Plätze) | B14: 2 | C14: days
A15: Travel & material per install | B15: 500 | C15: CHF
A16: Internal cost per install day | B16: 400 | C16: CHF / day (own time)
A18: RECURRING FEES
A19: Base fee (platform, service, box replacement) | B19: 50 | C19: CHF / month per range
A20: PayPerClay — baseline | B20: 0.02 | C20: CHF / clay (2 Rappen)
A21: PayPerClay — during financing | B21: 0.05 | C21: CHF / clay (5 Rappen)
A22: Financing: upfront share (Selbstkostenbeitrag) | B22: 0.5 | C22: of one-time total
A23: Financing: minimum monthly repayment | B23: 400 | C23: CHF / month
A25: VOLUME SCENARIOS — CLAYS / YEAR PER RANGE
A26: Low (small club, seasonal) | B26: 20000 | C26: Hegen-type club: ~112 h season, see reality check below
A27: Mid (active 4-Platz range) | B27: 60000 | C27: ≈ Hegen reality incl. club trainings + competitions
A28: High (busy commercial range) | B28: 250000 | C28: commercial range, open daily
A30: REFERENCE DEAL (4 PLÄTZE)
A31: Throwing machines | B31: 32 | C31: pcs
A32: Spare / relay SmartBoxes | B32: 6 | C32: pcs
A33: Nodes | B33: 4 | C33: 1 per Platz
A34: Hub | B34: 1 | C34: pcs
A36: RUNNING COSTS PER RANGE / YEAR
A37: Cloud hosting & connectivity | B37: 300 | C37: CHF / year
A38: Support effort | B38: 1000 | C38: CHF / year (≈ 20 h)
A39: Warranty box replacements | B39: 2 | C39: boxes / year
A40: Hub + Node amortization period | B40: 5 | C40: years
A42: GROWTH — 5-YEAR PROJECTION
A43: New ranges signed per year | B43: 2 | C43: 4 | D43: 6 | E43: 8 | F43: 10
A44: Avg SmartBoxes per range (incl. spares) | B44: 24 | C44: pcs
A45: Avg nodes per range | B45: 3 | C45: pcs
A46: Avg clays per range / year | B46: 80000 | C46: clays — mix of club and commercial ranges
A48: VOLUME REALITY CHECK — FLINTENSCHIESSANLAGE HEGEN
...

Sheet Inventory
A1: Inventory & Price List
A3: Item | B3: Description | C3: Unit cost (CHF) | D3: Sale price (CHF) | E3: Rental (CHF/mo) | F3: Margin (CHF, /yr for rentals) | G3: Margin %
A4: SmartBox | B4: Per machine + spares/relays; sold | C4: =Assumptions!B4+Assumptions!B5 -> 115 | D4: =Assumptions!B6 -> 250 | F4: =D4-C4 -> 135 | G4: =F4/D4 -> 0.54
A5: Node | B5: 1 per Platz; rented, stays our property | C5: =Assumptions!B7 -> 250 | E5: =Assumptions!B8 -> 25 | F5: =E5*12-C5/Assumptions!B40 -> 250 | G5: =F5/(E5*12) -> 0.83333333
A6: Hub | B6: 1 per range; rented, stays our property | C6: =Assumptions!B9 -> 400 | E6: =Assumptions!B10 -> 50 | F6: =E6*12-C6/Assumptions!B40 -> 520 | G6: =F6/(E6*12) -> 0.86666667
A7: Installation & setup | B7: Per 4-Platz range; on-site, config, training | C7: =Assumptions!B14*Assumptions!B16+Assumptions!B15 -> 1300 | D7: =Assumptions!B14*Assumptions!B13+Assumptions!B15 -> 2900 | F7: =D7-C7 -> 1600 | G7: =F7/D7 -> 0.55172414
A9: Note: unit costs are estimates — replace with real BOM once known (blue cells on Assumptions).

Sheet Reference Deal
A1: Reference Deal — 4 Plätze, 32 machines
A3: ONE-TIME (SALE + SETUP)
A4: Item | B4: Qty | C4: Unit price | D4: Revenue | E4: Unit cost | F4: Cost | G4: Margin
A5: SmartBoxes (machines + spares) | B5: =Assumptions!B31+Assumptions!B32 -> 38 | C5: =Assumptions!B6 -> 250 | D5: =B5*C5 -> 9500 | E5: =Inventory!C4 -> 115 | F5: =B5*E5 -> 4370 | G5: =D5-F5 -> 5130
A6: Installation & setup | B6: 1 | C6: =Inventory!D7 -> 2900 | D6: =B6*C6 -> 2900 | E6: =Inventory!C7 -> 1300 | F6: =B6*E6 -> 1300 | G6: =D6-F6 -> 1600
A7: Hub + Nodes (our capex — rented out) | F7: =Assumptions!B33*Assumptions!B7+Assumptions!B34*Assumptions!B9 -> 1400 | G7: =-F7 -> -1400
A8: Total one-time | D8: =SUM(D5:D7) -> 12400 | F8: =SUM(F5:F7) -> 7070 | G8: =SUM(G5:G7) -> 5330
A10: RECURRING PER YEAR
B11: Low | C11: Mid | D11: High
A12: Clays / year | B12: =Assumptions!B26 -> 20000 | C12: =Assumptions!B27 -> 60000 | D12: =Assumptions!B28 -> 250000
A13: Base fee | B13: =Assumptions!$B$19*12 -> 600 | C13: =Assumptions!$B$19*12 -> 600 | D13: =Assumptions!$B$19*12 -> 600
A14: Node rental | B14: =Assumptions!$B$33*Assumptions!$B$8*12 -> 1200 | C14: =Assumptions!$B$33*Assumptions!$B$8*12 -> 1200 | D14: =Assumptions!$B$33*Assumptions!$B$8*12 -> 1200
A15: Hub rental | B15: =Assumptions!$B$34*Assumptions!$B$10*12 -> 600 | C15: =Assumptions!$B$34*Assumptions!$B$10*12 -> 600 | D15: =Assumptions!$B$34*Assumptions!$B$10*12 -> 600
A16: PayPerClay (baseline) | B16: =B12*Assumptions!$B$20 -> 400 | C16: =C12*Assumptions!$B$20 -> 1200 | D16: =D12*Assumptions!$B$20 -> 5000
A17: Total recurring revenue | B17: =SUM(B13:B16) -> 2800 | C17: =SUM(C13:C16) -> 3600 | D17: =SUM(D13:D16) -> 7400
A18: Running costs (hosting, support, replacements, amortization) | B18: =Assumptions!$B$37+Assumptions!$B$38+Assumptions!$B$39*Inventory!$C$4+(Assumptions!$B$33*Assumptions!$B$7+Assumptions!$B$34*Assumptions!$B$9)/Assumptions!$B$40 -> 1810 | C18: =Assumptions!$B$37+Assumptions!$B$38+Assumptions!$B$39*Inventory!$C$4+(Assumptions!$B$33*Assumptions!$B$7+Assumptions!$B$34*Assumptions!$B$9)/Assumptions!$B$40 -> 1810 | D18: =Assumptions!$B$37+Assumptions!$B$38+Assumptions!$B$39*Inventory!$C$4+(Assumptions!$B$33*Assumptions!$B$7+Assumptions!$B$34*Assumptions!$B$9)/Assumptions!$B$40 -> 1810
A19: Recurring margin / year | B19: =B17-B18 -> 990 | C19: =C17-C18 -> 1790 | D19: =D17-D18 -> 5590
A20: Margin % | B20: =B19/B17 -> 0.35357143 | C20: =C19/C17 -> 0.49722222 | D20: =D19/D17 -> 0.75540541
A22: FINANCING VARIANT ("SELBSTKOSTENBEITRAG")
A23: One-time total (list price) | B23: =D8 -> 12400
A24: Upfront payment | B24: =B23*Assumptions!B22 -> 6200
A25: Financed balance | B25: =B23-B24 -> 6200
A26: Extra fee per clay (5 − 2 Rp) | B26: =Assumptions!B21-Assumptions!B20 -> 0.03
A27: Clays needed to repay | B27: =B25/B26 -> 206666.67
A28: Years to repay (Low / Mid / High) | B28: =$B$27/B12 -> 10.333333 | C28: =$B$27/C12 -> 3.4444444 | D28: =$B$27/D12 -> 0.82666667
A29: Max months with minimum repayment | B29: =B25/Assumptions!B23 -> 15.5

Sheet 5-Year Projection
A1: 5-Year Projection (CHF) — average range profile from Assumptions
A3: Year | B3: Y1 | C3: Y2 | D3: Y3 | E3: Y4 | F3: Y5
A4: New ranges signed | B4: =Assumptions!B43 -> 2 | C4: =Assumptions!C43 -> 4 | D4: =Assumptions!D43 -> 6 | E4: =Assumptions!E43 -> 8 | F4: =Assumptions!F43 -> 10
A5: Cumulative ranges | B5: =B4 -> 2 | C5: =B5+C4 -> 6 | D5: =C5+D4 -> 12 | E5: =D5+E4 -> 20 | F5: =E5+F4 -> 30
A6: Avg active ranges (new count ½ year) | B6: =B5-0.5*B4 -> 1 | C6: =C5-0.5*C4 -> 4 | D6: =D5-0.5*D4 -> 9 | E6: =E5-0.5*E4 -> 16 | F6: =F5-0.5*F4 -> 25
A8: ONE-TIME (HARDWARE SALES + SETUP)
A9: Revenue | B9: =B4*(Assumptions!$B$44*Assumptions!$B$6+Inventory!$D$7) -> 17800 | C9: =C4*(Assumptions!$B$44*Assumptions!$B$6+Inventory!$D$7) -> 35600 | D9: =D4*(Assumptions!$B$44*Assumptions!$B$6+Inventory!$D$7) -> 53400 | E9: =E4*(Assumptions!$B$44*Assumptions!$B$6+Inventory!$D$7) -> 71200 | F9: =F4*(Assumptions!$B$44*Assumptions!$B$6+Inventory!$D$7) -> 89000
A10: Costs (boxes, install, hub/node capex) | B10: =B4*(Assumptions!$B$44*Inventory!$C$4+Inventory!$C$7+Assumptions!$B$45*Assumptions!$B$7+Assumptions!$B$9) -> 10420 | C10: =C4*(Assumptions!$B$44*Inventory!$C$4+Inventory!$C$7+Assumptions!$B$45*Assumptions!$B$7+Assumptions!$B$9) -> 20840 | D10: =D4*(Assumptions!$B$44*Inventory!$C$4+Inventory!$C$7+Assumptions!$B$45*Assumptions!$B$7+Assumptions!$B$9) -> 31260 | E10: =E4*(Assumptions!$B$44*Inventory!$C$4+Inventory!$C$7+Assumptions!$B$45*Assumptions!$B$7+Assumptions!$B$9) -> 41680 | F10: =F4*(Assumptions!$B$44*Inventory!$C$4+Inventory!$C$7+Assumptions!$B$45*Assumptions!$B$7+Assumptions!$B$9) -> 52100
A11: One-time margin | B11: =B9-B10 -> 7380 | C11: =C9-C10 -> 14760 | D11: =D9-D10 -> 22140 | E11: =E9-E10 -> 29520 | F11: =F9-F10 -> 36900
A13: RECURRING (FEES + PAYPERCLAY)
A14: Revenue | B14: =B6*(Assumptions!$B$19*12+Assumptions!$B$45*Assumptions!$B$8*12+Assumptions!$B$10*12+Assumptions!$B$46*Assumptions!$B$20) -> 3700 | C14: =C6*(Assumptions!$B$19*12+Assumptions!$B$45*Assumptions!$B$8*12+Assumptions!$B$10*12+Assumptions!$B$46*Assumptions!$B$20) -> 14800 | D14: =D6*(Assumptions!$B$19*12+Assumptions!$B$45*Assumptions!$B$8*12+Assumptions!$B$10*12+Assumptions!$B$46*Assumptions!$B$20) -> 33300 | E14: =E6*(Assumptions!$B$19*12+Assumptions!$B$45*Assumptions!$B$8*12+Assumptions!$B$10*12+Assumptions!$B$46*Assumptions!$B$20) -> 59200 | F14: =F6*(Assumptions!$B$19*12+Assumptions!$B$45*Assumptions!$B$8*12+Assumptions!$B$10*12+Assumptions!$B$46*Assumptions!$B$20) -> 92500
A15: Running costs (hosting, support, replacements) | B15: =B6*(Assumptions!$B$37+Assumptions!$B$38+Assumptions!$B$39*Inventory!$C$4) -> 1530 | C15: =C6*(Assumptions!$B$37+Assumptions!$B$38+Assumptions!$B$39*Inventory!$C$4) -> 6120 | D15: =D6*(Assumptions!$B$37+Assumptions!$B$38+Assumptions!$B$39*Inventory!$C$4) -> 13770 | E15: =E6*(Assumptions!$B$37+Assumptions!$B$38+Assumptions!$B$39*Inventory!$C$4) -> 24480 | F15: =F6*(Assumptions!$B$37+Assumptions!$B$38+Assumptions!$B$39*Inventory!$C$4) -> 38250
A16: Recurring margin | B16: =B14-B15 -> 2170 | C16: =C14-C15 -> 8680 | D16: =D14-D15 -> 19530 | E16: =E14-E15 -> 34720 | F16: =F14-F15 -> 54250
A18: Total margin | B18: =B11+B16 -> 9550 | C18: =C11+C16 -> 23440 | D18: =D11+D16 -> 41670 | E18: =E11+E16 -> 64240 | F18: =F11+F16 -> 91150
A19: Cumulative margin | B19: =B18 -> 9550 | C19: =B19+C18 -> 32990 | D19: =C19+D18 -> 74660 | E19: =D19+E18 -> 138900 | F19: =E19+F18 -> 230050
A21: Excludes: your salaries, development time, marketing, taxes. This is contribution margin, not profit.
